multiprocessing.pool.RemoteTraceback: 
"""
Traceback (most recent call last):
  File "/N/u/zkachwal/Carbonate/miniconda3/lib/python3.7/multiprocessing/pool.py", line 121, in worker
    result = (True, func(*args, **kwds))
  File "create_fred.py", line 937, in compileClaimGraph1
    claim_g=cleanClaimGraph(claim_g,clean_claims[str(claim_ID)])
  File "create_fred.py", line 886, in cleanClaimGraph
    tsnodes=list(nx.topological_sort(temp_g))
  File "/N/u/zkachwal/Carbonate/miniconda3/lib/python3.7/site-packages/networkx/algorithms/dag.py", line 210, in topological_sort
    raise nx.NetworkXUnfeasible("Graph contains a cycle or graph changed "
networkx.exception.NetworkXUnfeasible: Graph contains a cycle or graph changed during iteration
"""

The above exception was the direct cause of the following exception:

Traceback (most recent call last):
  File "create_fred.py", line 1109, in <module>
    createFred(args.rdfpath,args.graphpath,args.fcgtype,args.init,args.passive,args.cpu,args.compilefred)
  File "create_fred.py", line 1057, in createFred
    output=sorted([p.get() for p in results],key=lambda x:x[0])
  File "create_fred.py", line 1057, in <listcomp>
    output=sorted([p.get() for p in results],key=lambda x:x[0])
  File "/N/u/zkachwal/Carbonate/miniconda3/lib/python3.7/multiprocessing/pool.py", line 657, in get
    raise self._value
networkx.exception.NetworkXUnfeasible: Graph contains a cycle or graph changed during iteration

real	0m5.637s
user	0m9.088s
sys	0m5.128s
multiprocessing.pool.RemoteTraceback: 
"""
Traceback (most recent call last):
  File "/N/u/zkachwal/Carbonate/miniconda3/lib/python3.7/multiprocessing/pool.py", line 121, in worker
    result = (True, func(*args, **kwds))
  File "create_fred.py", line 937, in compileClaimGraph1
    claim_g=cleanClaimGraph(claim_g,clean_claims[str(claim_ID)])
  File "create_fred.py", line 886, in cleanClaimGraph
    tsnodes=list(nx.topological_sort(temp_g))
  File "/N/u/zkachwal/Carbonate/miniconda3/lib/python3.7/site-packages/networkx/algorithms/dag.py", line 210, in topological_sort
    raise nx.NetworkXUnfeasible("Graph contains a cycle or graph changed "
networkx.exception.NetworkXUnfeasible: Graph contains a cycle or graph changed during iteration
"""

The above exception was the direct cause of the following exception:

Traceback (most recent call last):
  File "create_fred.py", line 1109, in <module>
    createFred(args.rdfpath,args.graphpath,args.fcgtype,args.init,args.passive,args.cpu,args.compilefred)
  File "create_fred.py", line 1057, in createFred
    output=sorted([p.get() for p in results],key=lambda x:x[0])
  File "create_fred.py", line 1057, in <listcomp>
    output=sorted([p.get() for p in results],key=lambda x:x[0])
  File "/N/u/zkachwal/Carbonate/miniconda3/lib/python3.7/multiprocessing/pool.py", line 657, in get
    raise self._value
networkx.exception.NetworkXUnfeasible: Graph contains a cycle or graph changed during iteration

real	0m7.507s
user	0m12.600s
sys	0m6.336s

real	0m9.726s
user	0m5.984s
sys	0m1.472s
