
real	0m26.315s
user	14m39.958s
sys	0m8.904s

real	1m18.865s
user	49m42.535s
sys	0m15.447s

real	0m19.231s
user	6m18.186s
sys	0m21.440s

real	0m58.856s
user	23m40.853s
sys	1m0.019s

real	0m8.453s
user	0m5.097s
sys	0m0.759s

real	0m25.166s
user	0m2.405s
sys	0m1.000s

real	1m16.306s
user	0m6.957s
sys	0m2.338s

real	0m4.576s
user	0m1.503s
sys	0m0.483s

real	1m9.165s
user	1m1.379s
sys	0m6.095s

real	0m2.980s
user	0m1.279s
sys	0m0.563s

real	0m4.392s
user	0m3.079s
sys	0m0.403s

real	0m5.133s
user	0m3.725s
sys	0m0.481s

real	0m2.495s
user	0m0.829s
sys	0m0.471s

real	0m2.952s
user	0m1.459s
sys	0m0.516s

real	0m3.165s
user	0m1.658s
sys	0m0.455s

real	0m2.210s
user	0m0.619s
sys	0m0.412s

real	145m44.762s
user	6788m33.870s
sys	15m12.549s

real	49m1.682s
user	2252m42.680s
sys	11m28.335s

real	2m1.206s
user	32m46.709s
sys	0m24.512s

real	0m35.188s
user	8m54.680s
sys	0m7.554s

real	2m3.620s
user	38m10.136s
sys	0m19.221s

real	0m52.169s
user	14m33.064s
sys	0m7.365s
multiprocessing.pool.RemoteTraceback: 
"""
Traceback (most recent call last):
  File "/N/u/zkachwal/Carbonate/miniconda3/lib/python3.7/site-packages/networkx/algorithms/shortest_paths/weighted.py", line 744, in multi_source_dijkstra
    return (dist[target], paths[target])
KeyError: 'db:Gross_domestic_product'

During handling of the above exception, another exception occurred:

Traceback (most recent call last):
  File "/N/u/zkachwal/Carbonate/miniconda3/lib/python3.7/multiprocessing/pool.py", line 121, in worker
    result = (True, func(*args, **kwds))
  File "find_shortest_paths.py", line 272, in find_paths_of_interest
    path_d1=nx.shortest_path(source_fcg,source=u,target=v,weight='dist')
  File "/N/u/zkachwal/Carbonate/miniconda3/lib/python3.7/site-packages/networkx/algorithms/shortest_paths/generic.py", line 172, in shortest_path
    paths = nx.dijkstra_path(G, source, target, weight)
  File "/N/u/zkachwal/Carbonate/miniconda3/lib/python3.7/site-packages/networkx/algorithms/shortest_paths/weighted.py", line 167, in dijkstra_path
    weight=weight)
  File "/N/u/zkachwal/Carbonate/miniconda3/lib/python3.7/site-packages/networkx/algorithms/shortest_paths/weighted.py", line 480, in single_source_dijkstra
    weight=weight)
  File "/N/u/zkachwal/Carbonate/miniconda3/lib/python3.7/site-packages/networkx/algorithms/shortest_paths/weighted.py", line 746, in multi_source_dijkstra
    raise nx.NetworkXNoPath("No path to {}.".format(target))
networkx.exception.NetworkXNoPath: No path to db:Gross_domestic_product.
"""

The above exception was the direct cause of the following exception:

Traceback (most recent call last):
  File "find_shortest_paths.py", line 413, in <module>
    find_shortest_paths(args.rdfpath,args.modelpath,args.graphpath,graph_types[args.graphtype],args.embedpath,"tfcg",args.fcgtype,args.fcgclass,args.cpu)
  File "find_shortest_paths.py", line 385, in find_shortest_paths
    output=sorted([p.get() for p in results],key=lambda x:x[0])
  File "find_shortest_paths.py", line 385, in <listcomp>
    output=sorted([p.get() for p in results],key=lambda x:x[0])
  File "/N/u/zkachwal/Carbonate/miniconda3/lib/python3.7/multiprocessing/pool.py", line 657, in get
    raise self._value
networkx.exception.NetworkXNoPath: No path to db:Gross_domestic_product.

real	0m33.051s
user	17m51.421s
sys	0m36.173s
multiprocessing.pool.RemoteTraceback: 
"""
Traceback (most recent call last):
  File "/N/u/zkachwal/Carbonate/miniconda3/lib/python3.7/site-packages/networkx/algorithms/shortest_paths/weighted.py", line 744, in multi_source_dijkstra
    return (dist[target], paths[target])
KeyError: 'db:United_States_Senate'

During handling of the above exception, another exception occurred:

Traceback (most recent call last):
  File "/N/u/zkachwal/Carbonate/miniconda3/lib/python3.7/multiprocessing/pool.py", line 121, in worker
    result = (True, func(*args, **kwds))
  File "find_shortest_paths.py", line 272, in find_paths_of_interest
    path_d1=nx.shortest_path(source_fcg,source=u,target=v,weight='dist')
  File "/N/u/zkachwal/Carbonate/miniconda3/lib/python3.7/site-packages/networkx/algorithms/shortest_paths/generic.py", line 172, in shortest_path
    paths = nx.dijkstra_path(G, source, target, weight)
  File "/N/u/zkachwal/Carbonate/miniconda3/lib/python3.7/site-packages/networkx/algorithms/shortest_paths/weighted.py", line 167, in dijkstra_path
    weight=weight)
  File "/N/u/zkachwal/Carbonate/miniconda3/lib/python3.7/site-packages/networkx/algorithms/shortest_paths/weighted.py", line 480, in single_source_dijkstra
    weight=weight)
  File "/N/u/zkachwal/Carbonate/miniconda3/lib/python3.7/site-packages/networkx/algorithms/shortest_paths/weighted.py", line 746, in multi_source_dijkstra
    raise nx.NetworkXNoPath("No path to {}.".format(target))
networkx.exception.NetworkXNoPath: No path to db:United_States_Senate.
"""

The above exception was the direct cause of the following exception:

Traceback (most recent call last):
  File "find_shortest_paths.py", line 413, in <module>
    find_shortest_paths(args.rdfpath,args.modelpath,args.graphpath,graph_types[args.graphtype],args.embedpath,"tfcg",args.fcgtype,args.fcgclass,args.cpu)
  File "find_shortest_paths.py", line 385, in find_shortest_paths
    output=sorted([p.get() for p in results],key=lambda x:x[0])
  File "find_shortest_paths.py", line 385, in <listcomp>
    output=sorted([p.get() for p in results],key=lambda x:x[0])
  File "/N/u/zkachwal/Carbonate/miniconda3/lib/python3.7/multiprocessing/pool.py", line 657, in get
    raise self._value
networkx.exception.NetworkXNoPath: No path to db:United_States_Senate.

real	0m31.538s
user	19m31.450s
sys	0m28.853s
