multiprocessing.pool.RemoteTraceback: 
"""
Traceback (most recent call last):
  File "/N/u/zkachwal/Carbonate/miniconda3/lib/python3.7/site-packages/networkx/algorithms/shortest_paths/weighted.py", line 744, in multi_source_dijkstra
    return (dist[target], paths[target])
KeyError: 'db:West_Virginia'

During handling of the above exception, another exception occurred:

Traceback (most recent call last):
  File "/N/u/zkachwal/Carbonate/miniconda3/lib/python3.7/multiprocessing/pool.py", line 121, in worker
    result = (True, func(*args, **kwds))
  File "find_shortest_paths.py", line 287, in find_paths_of_interest
    path_d2=nx.shortest_path(source_fcg,source=v,target=u,weight='dist')
  File "/N/u/zkachwal/Carbonate/miniconda3/lib/python3.7/site-packages/networkx/algorithms/shortest_paths/generic.py", line 172, in shortest_path
    paths = nx.dijkstra_path(G, source, target, weight)
  File "/N/u/zkachwal/Carbonate/miniconda3/lib/python3.7/site-packages/networkx/algorithms/shortest_paths/weighted.py", line 167, in dijkstra_path
    weight=weight)
  File "/N/u/zkachwal/Carbonate/miniconda3/lib/python3.7/site-packages/networkx/algorithms/shortest_paths/weighted.py", line 480, in single_source_dijkstra
    weight=weight)
  File "/N/u/zkachwal/Carbonate/miniconda3/lib/python3.7/site-packages/networkx/algorithms/shortest_paths/weighted.py", line 746, in multi_source_dijkstra
    raise nx.NetworkXNoPath("No path to {}.".format(target))
networkx.exception.NetworkXNoPath: No path to db:West_Virginia.
"""

The above exception was the direct cause of the following exception:

Traceback (most recent call last):
  File "find_shortest_paths.py", line 413, in <module>
    find_shortest_paths(args.rdfpath,args.modelpath,args.graphpath,args.embedpath,"tfcg",args.fcgtype,args.fcgclass,args.cpu)
  File "find_shortest_paths.py", line 389, in find_shortest_paths
    output=sorted([p.get() for p in results],key=lambda x:x[0])
  File "find_shortest_paths.py", line 389, in <listcomp>
    output=sorted([p.get() for p in results],key=lambda x:x[0])
  File "/N/u/zkachwal/Carbonate/miniconda3/lib/python3.7/multiprocessing/pool.py", line 657, in get
    raise self._value
networkx.exception.NetworkXNoPath: No path to db:West_Virginia.

real	1m8.004s
user	26m41.256s
sys	1m4.076s
multiprocessing.pool.RemoteTraceback: 
"""
Traceback (most recent call last):
  File "/N/u/zkachwal/Carbonate/miniconda3/lib/python3.7/site-packages/networkx/algorithms/shortest_paths/weighted.py", line 744, in multi_source_dijkstra
    return (dist[target], paths[target])
KeyError: 'db:United_States_Armed_Forces'

During handling of the above exception, another exception occurred:

Traceback (most recent call last):
  File "/N/u/zkachwal/Carbonate/miniconda3/lib/python3.7/multiprocessing/pool.py", line 121, in worker
    result = (True, func(*args, **kwds))
  File "find_shortest_paths.py", line 287, in find_paths_of_interest
    path_d2=nx.shortest_path(source_fcg,source=v,target=u,weight='dist')
  File "/N/u/zkachwal/Carbonate/miniconda3/lib/python3.7/site-packages/networkx/algorithms/shortest_paths/generic.py", line 172, in shortest_path
    paths = nx.dijkstra_path(G, source, target, weight)
  File "/N/u/zkachwal/Carbonate/miniconda3/lib/python3.7/site-packages/networkx/algorithms/shortest_paths/weighted.py", line 167, in dijkstra_path
    weight=weight)
  File "/N/u/zkachwal/Carbonate/miniconda3/lib/python3.7/site-packages/networkx/algorithms/shortest_paths/weighted.py", line 480, in single_source_dijkstra
    weight=weight)
  File "/N/u/zkachwal/Carbonate/miniconda3/lib/python3.7/site-packages/networkx/algorithms/shortest_paths/weighted.py", line 746, in multi_source_dijkstra
    raise nx.NetworkXNoPath("No path to {}.".format(target))
networkx.exception.NetworkXNoPath: No path to db:United_States_Armed_Forces.
"""

The above exception was the direct cause of the following exception:

Traceback (most recent call last):
  File "find_shortest_paths.py", line 413, in <module>
    find_shortest_paths(args.rdfpath,args.modelpath,args.graphpath,args.embedpath,"tfcg",args.fcgtype,args.fcgclass,args.cpu)
  File "find_shortest_paths.py", line 389, in find_shortest_paths
    output=sorted([p.get() for p in results],key=lambda x:x[0])
  File "find_shortest_paths.py", line 389, in <listcomp>
    output=sorted([p.get() for p in results],key=lambda x:x[0])
  File "/N/u/zkachwal/Carbonate/miniconda3/lib/python3.7/multiprocessing/pool.py", line 657, in get
    raise self._value
networkx.exception.NetworkXNoPath: No path to db:United_States_Armed_Forces.

real	0m54.040s
user	18m10.120s
sys	0m36.404s
