
real	168m17.140s
user	7827m37.020s
sys	31m20.424s
multiprocessing.pool.RemoteTraceback: 
"""
Traceback (most recent call last):
  File "/N/u/zkachwal/Carbonate/miniconda3/lib/python3.7/multiprocessing/pool.py", line 121, in worker
    result = (True, func(*args, **kwds))
  File "find_shortest_paths.py", line 252, in find_paths_of_interest
    source_fcg=create_weighted(p,rdf_path,model_path,graph_path,embed_path,source_claim_type,source_fcg_type+'-'+str(claimID),fcg_class,graph_type)
  File "find_shortest_paths.py", line 136, in create_weighted
    vIX=nodes_labels[nodes_labels['node_label']==v].index[0]
  File "/N/u/zkachwal/Carbonate/miniconda3/lib/python3.7/site-packages/pandas/core/indexes/base.py", line 3929, in __getitem__
    return getitem(key)
IndexError: index 0 is out of bounds for axis 0 with size 0
"""

The above exception was the direct cause of the following exception:

Traceback (most recent call last):
  File "find_shortest_paths.py", line 382, in <module>
    find_shortest_paths(args.rdfpath,args.modelpath,args.graphpath,args.embedpath,"tfcg",args.fcgtype,args.fcgclass,args.graphtype,args.cpu)
  File "find_shortest_paths.py", line 357, in find_shortest_paths
    output=sorted([p.get() for p in results],key=lambda x:x[0])
  File "find_shortest_paths.py", line 357, in <listcomp>
    output=sorted([p.get() for p in results],key=lambda x:x[0])
  File "/N/u/zkachwal/Carbonate/miniconda3/lib/python3.7/multiprocessing/pool.py", line 657, in get
    raise self._value
IndexError: index 0 is out of bounds for axis 0 with size 0

real	0m52.157s
user	24m7.536s
sys	0m36.304s
multiprocessing.pool.RemoteTraceback: 
"""
Traceback (most recent call last):
  File "/N/u/zkachwal/Carbonate/miniconda3/lib/python3.7/multiprocessing/pool.py", line 121, in worker
    result = (True, func(*args, **kwds))
  File "find_shortest_paths.py", line 255, in find_paths_of_interest
    source_fcg=create_weighted(p,rdf_path,model_path,graph_path,embed_path,source_claim_type,source_fcg_type,fcg_class,graph_type)
  File "find_shortest_paths.py", line 136, in create_weighted
    vIX=nodes_labels[nodes_labels['node_label']==v].index[0]
  File "/N/u/zkachwal/Carbonate/miniconda3/lib/python3.7/site-packages/pandas/core/indexes/base.py", line 3929, in __getitem__
    return getitem(key)
IndexError: index 0 is out of bounds for axis 0 with size 0
"""

The above exception was the direct cause of the following exception:

Traceback (most recent call last):
  File "find_shortest_paths.py", line 382, in <module>
    find_shortest_paths(args.rdfpath,args.modelpath,args.graphpath,args.embedpath,"tfcg",args.fcgtype,args.fcgclass,args.graphtype,args.cpu)
  File "find_shortest_paths.py", line 357, in find_shortest_paths
    output=sorted([p.get() for p in results],key=lambda x:x[0])
  File "find_shortest_paths.py", line 357, in <listcomp>
    output=sorted([p.get() for p in results],key=lambda x:x[0])
  File "/N/u/zkachwal/Carbonate/miniconda3/lib/python3.7/multiprocessing/pool.py", line 657, in get
    raise self._value
IndexError: index 0 is out of bounds for axis 0 with size 0

real	0m29.150s
user	9m45.664s
sys	0m50.396s
