multiprocessing.pool.RemoteTraceback: 
"""
Traceback (most recent call last):
  File "/N/u/zkachwal/Carbonate/miniconda3/lib/python3.7/multiprocessing/pool.py", line 121, in worker
    result = (True, func(*args, **kwds))
  File "find_shortest_paths.py", line 252, in find_paths_of_interest
    source_fcg=create_weighted(p,rdf_path,model_path,graph_path,embed_path,source_claim_type,source_fcg_type+'-'+str(claimID),fcg_class,graph_type)
  File "find_shortest_paths.py", line 149, in create_weighted
    fcg.edges[u,v].update(data)
  File "/N/u/zkachwal/Carbonate/miniconda3/lib/python3.7/site-packages/networkx/classes/reportviews.py", line 1106, in __getitem__
    u, v, k = e
ValueError: not enough values to unpack (expected 3, got 2)
"""

The above exception was the direct cause of the following exception:

Traceback (most recent call last):
  File "find_shortest_paths.py", line 382, in <module>
    find_shortest_paths(args.rdfpath,args.modelpath,args.graphpath,args.embedpath,"tfcg",args.fcgtype,args.fcgclass,args.graphtype,args.cpu)
  File "find_shortest_paths.py", line 357, in find_shortest_paths
    output=sorted([p.get() for p in results],key=lambda x:x[0])
  File "find_shortest_paths.py", line 357, in <listcomp>
    output=sorted([p.get() for p in results],key=lambda x:x[0])
  File "/N/u/zkachwal/Carbonate/miniconda3/lib/python3.7/multiprocessing/pool.py", line 657, in get
    raise self._value
ValueError: not enough values to unpack (expected 3, got 2)

real	1m17.850s
user	52m14.540s
sys	0m34.212s
