multiprocessing.pool.RemoteTraceback: 
"""
Traceback (most recent call last):
  File "/N/u/zkachwal/Carbonate/miniconda3/lib/python3.7/multiprocessing/pool.py", line 121, in worker
    result = (True, func(*args, **kwds))
  File "find_shortest_paths.py", line 225, in find_paths_of_interest
    source_fcg=create_weighted(p,rdf_path,model_path,graph_path,embed_path,source_claim_type,source_fcg_type,fcg_class)
  File "find_shortest_paths.py", line 138, in create_weighted
    data=min(fcg.get_edge_data(u,v).items(), key=lambda x:x[1]['dist'])[1]
  File "find_shortest_paths.py", line 138, in <lambda>
    data=min(fcg.get_edge_data(u,v).items(), key=lambda x:x[1]['dist'])[1]
KeyError: 'dist'
"""

The above exception was the direct cause of the following exception:

Traceback (most recent call last):
  File "find_shortest_paths.py", line 343, in <module>
    find_shortest_paths(args.rdfpath,args.modelpath,args.graphpath,args.embedpath,"tfcg",args.fcgtype,args.fcgclass,args.cpu)
  File "find_shortest_paths.py", line 319, in find_shortest_paths
    output=sorted([p.get() for p in results],key=lambda x:x[0])
  File "find_shortest_paths.py", line 319, in <listcomp>
    output=sorted([p.get() for p in results],key=lambda x:x[0])
  File "/N/u/zkachwal/Carbonate/miniconda3/lib/python3.7/multiprocessing/pool.py", line 657, in get
    raise self._value
KeyError: 'dist'

real	0m19.049s
user	6m1.748s
sys	0m47.004s
multiprocessing.pool.RemoteTraceback: 
"""
Traceback (most recent call last):
  File "/N/u/zkachwal/Carbonate/miniconda3/lib/python3.7/multiprocessing/pool.py", line 121, in worker
    result = (True, func(*args, **kwds))
  File "find_shortest_paths.py", line 240, in find_paths_of_interest
    data['weight']=data['dist']
KeyError: 'dist'
"""

The above exception was the direct cause of the following exception:

Traceback (most recent call last):
  File "find_shortest_paths.py", line 343, in <module>
    find_shortest_paths(args.rdfpath,args.modelpath,args.graphpath,args.embedpath,"tfcg",args.fcgtype,args.fcgclass,args.cpu)
  File "find_shortest_paths.py", line 319, in find_shortest_paths
    output=sorted([p.get() for p in results],key=lambda x:x[0])
  File "find_shortest_paths.py", line 319, in <listcomp>
    output=sorted([p.get() for p in results],key=lambda x:x[0])
  File "/N/u/zkachwal/Carbonate/miniconda3/lib/python3.7/multiprocessing/pool.py", line 657, in get
    raise self._value
KeyError: 'dist'

real	0m18.282s
user	8m27.984s
sys	0m29.020s
