multiprocessing.pool.RemoteTraceback: 
"""
Traceback (most recent call last):
  File "/N/u/zkachwal/Carbonate/miniconda3/lib/python3.7/multiprocessing/pool.py", line 121, in worker
    result = (True, func(*args, **kwds))
  File "find_shortest_paths.py", line 238, in find_paths_of_interest
    eu=list(source_fcg.in_edges(u,data=True))[0]
IndexError: list index out of range
"""

The above exception was the direct cause of the following exception:

Traceback (most recent call last):
  File "find_shortest_paths.py", line 436, in <module>
    find_shortest_paths(args.rdfpath,args.modelpath,args.graphpath,graph_types[args.graphtype],args.embedpath,"tfcg",args.fcgtype,args.fcgclass,args.cpu)
  File "find_shortest_paths.py", line 408, in find_shortest_paths
    output=sorted([p.get() for p in results],key=lambda x:x[0])
  File "find_shortest_paths.py", line 408, in <listcomp>
    output=sorted([p.get() for p in results],key=lambda x:x[0])
  File "/N/u/zkachwal/Carbonate/miniconda3/lib/python3.7/multiprocessing/pool.py", line 657, in get
    raise self._value
IndexError: list index out of range

real	2m20.128s
user	56m40.227s
sys	0m43.140s
multiprocessing.pool.RemoteTraceback: 
"""
Traceback (most recent call last):
  File "/N/u/zkachwal/Carbonate/miniconda3/lib/python3.7/multiprocessing/pool.py", line 121, in worker
    result = (True, func(*args, **kwds))
  File "find_shortest_paths.py", line 238, in find_paths_of_interest
    eu=list(source_fcg.in_edges(u,data=True))[0]
IndexError: list index out of range
"""

The above exception was the direct cause of the following exception:

Traceback (most recent call last):
  File "find_shortest_paths.py", line 436, in <module>
    find_shortest_paths(args.rdfpath,args.modelpath,args.graphpath,graph_types[args.graphtype],args.embedpath,"tfcg",args.fcgtype,args.fcgclass,args.cpu)
  File "find_shortest_paths.py", line 408, in find_shortest_paths
    output=sorted([p.get() for p in results],key=lambda x:x[0])
  File "find_shortest_paths.py", line 408, in <listcomp>
    output=sorted([p.get() for p in results],key=lambda x:x[0])
  File "/N/u/zkachwal/Carbonate/miniconda3/lib/python3.7/multiprocessing/pool.py", line 657, in get
    raise self._value
IndexError: list index out of range

real	0m52.466s
user	36m0.158s
sys	0m29.989s
